--- Logging error ---
Traceback (most recent call last):
  File "c:\python\lib\logging\__init__.py", line 1037, in emit
    stream.write(msg + self.terminator)
OSError: [WinError 6] 句柄无效。
Call stack:
  File "c:\python\lib\runpy.py", line 193, in _run_module_as_main
    "__main__", mod_spec)
  File "c:\python\lib\runpy.py", line 85, in _run_code
    exec(code, run_globals)
  File "C:\Python\Scripts\pytest.exe\__main__.py", line 7, in <module>
    sys.exit(main())
  File "c:\python\lib\site-packages\_pytest\config\__init__.py", line 125, in main
    config=config
  File "c:\python\lib\site-packages\pluggy\hooks.py", line 286, in __call__
    return self._hookexec(self, self.get_hookimpls(), kwargs)
  File "c:\python\lib\site-packages\pluggy\manager.py", line 93, in _hookexec
    return self._inner_hookexec(hook, methods, kwargs)
  File "c:\python\lib\site-packages\pluggy\manager.py", line 87, in <lambda>
    firstresult=hook.spec.opts.get("firstresult") if hook.spec else False,
  File "c:\python\lib\site-packages\pluggy\callers.py", line 187, in _multicall
    res = hook_impl.function(*args)
  File "c:\python\lib\site-packages\_pytest\main.py", line 240, in pytest_cmdline_main
    return wrap_session(config, _main)
  File "c:\python\lib\site-packages\_pytest\main.py", line 191, in wrap_session
    session.exitstatus = doit(config, session) or 0
  File "c:\python\lib\site-packages\_pytest\main.py", line 247, in _main
    config.hook.pytest_runtestloop(session=session)
  File "c:\python\lib\site-packages\pluggy\hooks.py", line 286, in __call__
    return self._hookexec(self, self.get_hookimpls(), kwargs)
  File "c:\python\lib\site-packages\pluggy\manager.py", line 93, in _hookexec
    return self._inner_hookexec(hook, methods, kwargs)
  File "c:\python\lib\site-packages\pluggy\manager.py", line 87, in <lambda>
    firstresult=hook.spec.opts.get("firstresult") if hook.spec else False,
  File "c:\python\lib\site-packages\pluggy\callers.py", line 187, in _multicall
    res = hook_impl.function(*args)
  File "c:\python\lib\site-packages\_pytest\main.py", line 272, in pytest_runtestloop
    item.config.hook.pytest_runtest_protocol(item=item, nextitem=nextitem)
  File "c:\python\lib\site-packages\pluggy\hooks.py", line 286, in __call__
    return self._hookexec(self, self.get_hookimpls(), kwargs)
  File "c:\python\lib\site-packages\pluggy\manager.py", line 93, in _hookexec
    return self._inner_hookexec(hook, methods, kwargs)
  File "c:\python\lib\site-packages\pluggy\manager.py", line 87, in <lambda>
    firstresult=hook.spec.opts.get("firstresult") if hook.spec else False,
  File "c:\python\lib\site-packages\pluggy\callers.py", line 187, in _multicall
    res = hook_impl.function(*args)
  File "c:\python\lib\site-packages\_pytest\runner.py", line 85, in pytest_runtest_protocol
    runtestprotocol(item, nextitem=nextitem)
  File "c:\python\lib\site-packages\_pytest\runner.py", line 94, in runtestprotocol
    rep = call_and_report(item, "setup", log)
  File "c:\python\lib\site-packages\_pytest\runner.py", line 186, in call_and_report
    call = call_runtest_hook(item, when, **kwds)
  File "c:\python\lib\site-packages\_pytest\runner.py", line 217, in call_runtest_hook
    lambda: ihook(item=item, **kwds), when=when, reraise=reraise
  File "c:\python\lib\site-packages\_pytest\runner.py", line 244, in from_call
    result = func()
  File "c:\python\lib\site-packages\_pytest\runner.py", line 217, in <lambda>
    lambda: ihook(item=item, **kwds), when=when, reraise=reraise
  File "c:\python\lib\site-packages\pluggy\hooks.py", line 286, in __call__
    return self._hookexec(self, self.get_hookimpls(), kwargs)
  File "c:\python\lib\site-packages\pluggy\manager.py", line 93, in _hookexec
    return self._inner_hookexec(hook, methods, kwargs)
  File "c:\python\lib\site-packages\pluggy\manager.py", line 87, in <lambda>
    firstresult=hook.spec.opts.get("firstresult") if hook.spec else False,
  File "c:\python\lib\site-packages\pluggy\callers.py", line 187, in _multicall
    res = hook_impl.function(*args)
  File "c:\python\lib\site-packages\auto_checklog.py", line 21, in pytest_runtest_setup
    test_steps.log_new_func(item.name, str(item.fspath) )
  File "c:\python\lib\site-packages\test_steps\__init__.py", line 109, in log_new_func
    __step_info.new_func(name, path)
  File "c:\python\lib\site-packages\test_steps\__init__.py", line 87, in new_func
    self.__log_case()
  File "c:\python\lib\site-packages\test_steps\__init__.py", line 90, in __log_case
    self.step_logger.info("------------------------------------------------------")
Message: '------------------------------------------------------'
Arguments: ()
--- Logging error ---
Traceback (most recent call last):
  File "c:\python\lib\logging\__init__.py", line 1037, in emit
    stream.write(msg + self.terminator)
OSError: [WinError 6] 句柄无效。
Call stack:
  File "c:\python\lib\runpy.py", line 193, in _run_module_as_main
    "__main__", mod_spec)
  File "c:\python\lib\runpy.py", line 85, in _run_code
    exec(code, run_globals)
  File "C:\Python\Scripts\pytest.exe\__main__.py", line 7, in <module>
    sys.exit(main())
  File "c:\python\lib\site-packages\_pytest\config\__init__.py", line 125, in main
    config=config
  File "c:\python\lib\site-packages\pluggy\hooks.py", line 286, in __call__
    return self._hookexec(self, self.get_hookimpls(), kwargs)
  File "c:\python\lib\site-packages\pluggy\manager.py", line 93, in _hookexec
    return self._inner_hookexec(hook, methods, kwargs)
  File "c:\python\lib\site-packages\pluggy\manager.py", line 87, in <lambda>
    firstresult=hook.spec.opts.get("firstresult") if hook.spec else False,
  File "c:\python\lib\site-packages\pluggy\callers.py", line 187, in _multicall
    res = hook_impl.function(*args)
  File "c:\python\lib\site-packages\_pytest\main.py", line 240, in pytest_cmdline_main
    return wrap_session(config, _main)
  File "c:\python\lib\site-packages\_pytest\main.py", line 191, in wrap_session
    session.exitstatus = doit(config, session) or 0
  File "c:\python\lib\site-packages\_pytest\main.py", line 247, in _main
    config.hook.pytest_runtestloop(session=session)
  File "c:\python\lib\site-packages\pluggy\hooks.py", line 286, in __call__
    return self._hookexec(self, self.get_hookimpls(), kwargs)
  File "c:\python\lib\site-packages\pluggy\manager.py", line 93, in _hookexec
    return self._inner_hookexec(hook, methods, kwargs)
  File "c:\python\lib\site-packages\pluggy\manager.py", line 87, in <lambda>
    firstresult=hook.spec.opts.get("firstresult") if hook.spec else False,
  File "c:\python\lib\site-packages\pluggy\callers.py", line 187, in _multicall
    res = hook_impl.function(*args)
  File "c:\python\lib\site-packages\_pytest\main.py", line 272, in pytest_runtestloop
    item.config.hook.pytest_runtest_protocol(item=item, nextitem=nextitem)
  File "c:\python\lib\site-packages\pluggy\hooks.py", line 286, in __call__
    return self._hookexec(self, self.get_hookimpls(), kwargs)
  File "c:\python\lib\site-packages\pluggy\manager.py", line 93, in _hookexec
    return self._inner_hookexec(hook, methods, kwargs)
  File "c:\python\lib\site-packages\pluggy\manager.py", line 87, in <lambda>
    firstresult=hook.spec.opts.get("firstresult") if hook.spec else False,
  File "c:\python\lib\site-packages\pluggy\callers.py", line 187, in _multicall
    res = hook_impl.function(*args)
  File "c:\python\lib\site-packages\_pytest\runner.py", line 85, in pytest_runtest_protocol
    runtestprotocol(item, nextitem=nextitem)
  File "c:\python\lib\site-packages\_pytest\runner.py", line 94, in runtestprotocol
    rep = call_and_report(item, "setup", log)
  File "c:\python\lib\site-packages\_pytest\runner.py", line 186, in call_and_report
    call = call_runtest_hook(item, when, **kwds)
  File "c:\python\lib\site-packages\_pytest\runner.py", line 217, in call_runtest_hook
    lambda: ihook(item=item, **kwds), when=when, reraise=reraise
  File "c:\python\lib\site-packages\_pytest\runner.py", line 244, in from_call
    result = func()
  File "c:\python\lib\site-packages\_pytest\runner.py", line 217, in <lambda>
    lambda: ihook(item=item, **kwds), when=when, reraise=reraise
  File "c:\python\lib\site-packages\pluggy\hooks.py", line 286, in __call__
    return self._hookexec(self, self.get_hookimpls(), kwargs)
  File "c:\python\lib\site-packages\pluggy\manager.py", line 93, in _hookexec
    return self._inner_hookexec(hook, methods, kwargs)
  File "c:\python\lib\site-packages\pluggy\manager.py", line 87, in <lambda>
    firstresult=hook.spec.opts.get("firstresult") if hook.spec else False,
  File "c:\python\lib\site-packages\pluggy\callers.py", line 187, in _multicall
    res = hook_impl.function(*args)
  File "c:\python\lib\site-packages\auto_checklog.py", line 21, in pytest_runtest_setup
    test_steps.log_new_func(item.name, str(item.fspath) )
  File "c:\python\lib\site-packages\test_steps\__init__.py", line 109, in log_new_func
    __step_info.new_func(name, path)
  File "c:\python\lib\site-packages\test_steps\__init__.py", line 87, in new_func
    self.__log_case()
  File "c:\python\lib\site-packages\test_steps\__init__.py", line 91, in __log_case
    self.step_logger.info("Func %s in file: %s" % (self.case_name, self.file_name))
Message: 'Func test_operationCallback in file: C:\\liqi\\autoApiTestLiqi\\testcases\\Test_case2_pushMiniPro.py'
Arguments: ()
2020-06-23 18:07:43,223 - process: 129768 - Test_case2_pushMiniPro.py - 日志 - 233 - Test_case2_pushMiniPro - INFO - operationCallback接口的地址是:http://172.16.117.151:8080/wechat-api/api/wechat/operationCallback
2020-06-23 18:07:43,224 - process: 129768 - Test_case2_pushMiniPro.py - 日志 - 250 - Test_case2_pushMiniPro - INFO - operationCallback接口的入参是：{'desc': '轮询到自动操作指令operationId:286 operationType:41 hasNewVersionfalse', 'operationId': 1272, 'operationType': 36, 'state': -2, 'wechatId': 'wxid_ss245739845', 'versionName': '3.1.13', 'versionCode': '97', 'wechatAccount': 'wxid_ss245739845', 'wechatVersion': '7.0.5', 'wechatVersionCode': '1440', 'source': 'app_root', 'loginAccount': '${account}', 'phoneDeviceId': '2cd6f7c3b0a15b2f', 'channel': 'platform'}
2020-06-23 18:07:43,224 - process: 129768 - Test_case2_pushMiniPro.py - 日志 - 251 - Test_case2_pushMiniPro - INFO - =====开始请求operationCallback接口
2020-06-23 18:07:43,502 - process: 129768 - Test_case2_pushMiniPro.py - 日志 - 253 - Test_case2_pushMiniPro - INFO - ============接口响应结果：{'flag': 1, 'message': '', 'data': ''}
2020-06-23 18:07:43,503 - process: 129768 - Test_case2_pushMiniPro.py - 日志 - 256 - Test_case2_pushMiniPro - INFO - 状态码的值是: 200
2020-06-23 18:07:43,504 - process: 129768 - Test_case2_pushMiniPro.py - 日志 - 259 - Test_case2_pushMiniPro - INFO - ===状态码正确======
